<?xml version="1.0" ?>
<robot name="carA">
  <joint name="carA__link_0_JOINT_0" type="fixed">
    <parent link="carA__base_link"/>
    <child link="carA__link_1"/>
    <origin rpy="0  0  0" xyz="-0.42423 -0.22474 -0.1322"/>
    <axis xyz="0  0  0"/>
    <limit effort="0" lower="0" upper="0" velocity="0"/>
  </joint>

  <joint name="carA__link_0_JOINT_1" type="fixed">
    <parent link="carA__base_link"/>
    <child link="carA__link_1_clone"/>
    <origin rpy="0  0  0" xyz="-0.42423  0.22525 -0.1322"/>
    <axis xyz="0  0  0"/>
    <limit effort="0" lower="0" upper="0" velocity="0"/>
  </joint>

  <joint name="carA__link_0_JOINT_2" type="fixed">
    <parent link="carA__base_link"/>
    <child link="carA__link_1_clone_0"/>
    <origin rpy="0  0  0" xyz="0.42576 -0.22474 -0.1322"/>
    <axis xyz="0  0  0"/>
    <limit effort="0" lower="0" upper="0" velocity="0"/>
  </joint>

  <joint name="carA__link_0_JOINT_3" type="fixed">
    <parent link="carA__base_link"/>
    <child link="carA__link_1_clone_1"/>
    <origin rpy="0  0  0" xyz="0.42576  0.22525 -0.1322"/>
    <axis xyz="0  0  0"/>
    <limit effort="0" lower="0" upper="0" velocity="0"/>
  </joint>

  <joint name="carA__link_0_JOINT_4" type="continuous">
    <parent link="carA__base_link"/>
    <child link="carA__left_wheel"/>
    <origin rpy="1.5707  0      0" xyz="0.00076 -0.35 -0.0572"/>
    <axis xyz="1  0  0"/>
    <limit effort="-1.0" lower="-1.79769e+308" upper="1.79769e+308" velocity="-1.0"/>
  </joint>

  <joint name="carA__link_0_JOINT_5" type="continuous">
    <parent link="carA__base_link"/>
    <child link="carA__right_wheel"/>
    <origin rpy="1.5707  0      0" xyz="0.00076  0.35 -0.0572"/>
    <axis xyz="1  0  0"/>
    <limit effort="-1.0" lower="-1.79769e+308" upper="1.79769e+308" velocity="-1.0"/>
  </joint>
  
  <link name="carA__base_link">
    <inertial>
      <mass value="10"/>
      <origin rpy="0  0  0" xyz="0  0  0"/>
      <inertia ixx="1.66667" ixy="0" ixz="0" iyy="1.66667" iyz="0" izz="1.66667"/>
    </inertial>
    <collision name="carA__collision">
      <origin rpy="0       0      -0.04158" xyz="0.00076  0.00025  0.09279"/>
      <geometry>
        <box size="1 0.6 0.3"/>
      </geometry>
    </collision>
    <visual name="carA__visual">
      <origin rpy="0       0      -0.04158" xyz="0.00076  0.00025  0.09279"/>
      <geometry>
        <box size="1 0.6 0.3"/>
      </geometry>
    </visual>
  </link>

  <link name="carA__link_1">
    <inertial>
      <mass value="1"/>
      <origin rpy="0  0  0" xyz="0  0  0"/>
      <inertia ixx="0.1" ixy="0" ixz="0" iyy="0.1" iyz="0" izz="0.1"/>
    </inertial>
    <collision name="carA__collision">
      <origin rpy="0  0  0" xyz="0  0  0"/>
      <geometry>
        <sphere radius="0.075"/>
      </geometry>
    </collision>
    <visual name="carA__visual">
      <origin rpy="0  0  0" xyz="0  0  0"/>
      <geometry>
        <sphere radius="0.075"/>
      </geometry>
    </visual>
  </link>

  <link name="carA__link_1_clone">
    <inertial>
      <mass value="1"/>
      <origin rpy="0  0  0" xyz="0  0  0"/>
      <inertia ixx="0.1" ixy="0" ixz="0" iyy="0.1" iyz="0" izz="0.1"/>
    </inertial>
    <collision name="carA__collision">
      <origin rpy="0  0  0" xyz="0  0  0"/>
      <geometry>
        <sphere radius="0.075"/>
      </geometry>
    </collision>
    <visual name="carA__visual">
      <origin rpy="0  0  0" xyz="0  0  0"/>
      <geometry>
        <sphere radius="0.075"/>
      </geometry>
    </visual>
  </link>

  <link name="carA__link_1_clone_0">
    <inertial>
      <mass value="1"/>
      <origin rpy="0  0  0" xyz="0  0  0"/>
      <inertia ixx="0.1" ixy="0" ixz="0" iyy="0.1" iyz="0" izz="0.1"/>
    </inertial>
    <collision name="carA__collision">
      <origin rpy="0  0  0" xyz="0  0  0"/>
      <geometry>
        <sphere radius="0.075"/>
      </geometry>
    </collision>
    <visual name="carA__visual">
      <origin rpy="0  0  0" xyz="0  0  0"/>
      <geometry>
        <sphere radius="0.075"/>
      </geometry>
    </visual>
  </link>

  <link name="carA__link_1_clone_1">
    <inertial>
      <mass value="1"/>
      <origin rpy="0  0  0" xyz="0  0  0"/>
      <inertia ixx="0.1" ixy="0" ixz="0" iyy="0.1" iyz="0" izz="0.1"/>
    </inertial>
    <collision name="carA__collision">
      <origin rpy="0  0  0" xyz="0  0  0"/>
      <geometry>
        <sphere radius="0.075"/>
      </geometry>
    </collision>
    <visual name="carA__visual">
      <origin rpy="0  0  0" xyz="0  0  0"/>
      <geometry>
        <sphere radius="0.075"/>
      </geometry>
    </visual>
  </link>

  <link name="carA__left_wheel">
    <inertial>
      <mass value="0.1"/>
      <origin rpy="0  0  0" xyz="0  0  0"/>
      <inertia ixx="0.145833" ixy="0" ixz="0" iyy="0.145833" iyz="0" izz="0.125"/>
    </inertial>
    <collision name="carA__collision">
      <origin rpy="0  0  0" xyz="0  0  0"/>
      <geometry>
        <cylinder length="0.1" radius="0.15"/>
      </geometry>
    </collision>
    <visual name="carA__visual">
      <origin rpy="0  0  0" xyz="0  0  0"/>
      <geometry>
        <cylinder length="0.1" radius="0.15"/>
      </geometry>
    </visual>
  </link>

  <link name="carA__right_wheel">
    <inertial>
      <mass value="0.1"/>
      <origin rpy="0  0  0" xyz="0  0  0"/>
      <inertia ixx="0.145833" ixy="0" ixz="0" iyy="0.145833" iyz="0" izz="0.125"/>
    </inertial>
    <collision name="carA__collision">
      <origin rpy="0  0  0" xyz="0  0  0"/>
      <geometry>
        <cylinder length="0.1" radius="0.15"/>
      </geometry>
    </collision>
    <visual name="carA__visual">
      <origin rpy="0  0  0" xyz="0  0  0"/>
      <geometry>
        <cylinder length="0.1" radius="0.15"/>
      </geometry>
    </visual>
  </link>


  
</robot>
